Workbook

Sheet Summary
B2: VERTIV HOLDINGS (VRT)
B3: $ in millions, fiscal years ending Dec 31, shaded columns are forecasts
B5: Key Outputs | C5: 2023A | D5: 2024A | E5: 2025A | F5: 2026E | G5: 2027E | H5: 2028E | I5: 2029E
B6: Net Sales | C6: =Model!C16 -> 6863.2 | D6: =Model!D16 -> 8011.8 | E6: =Model!E16 -> 10229.9 | F6: =Model!F16 -> 13605.767 | G6: =Model!G16 -> 17551.439 | H6: =Model!H16 -> 21412.756 | I6: =Model!I16 -> 25052.925
B7: Sales Growth | D7: =D6/C6-1 -> 0.16735634 | E7: =E6/D6-1 -> 0.27685414 | F7: =F6/E6-1 -> 0.33 | G7: =G6/F6-1 -> 0.29 | H7: =H6/G6-1 -> 0.22 | I7: =I6/H6-1 -> 0.17
B8: Gross Margin | C8: =Model!C22/Model!C16 -> 0.34976396 | D8: =Model!D22/Model!D16 -> 0.3662348 | E8: =Model!E22/Model!E16 -> 0.36317071 | F8: =Model!F22/Model!F16 -> 0.36 | G8: =Model!G22/Model!G16 -> 0.36 | H8: =Model!H22/Model!H16 -> 0.36 | I8: =Model!I22/Model!I16 -> 0.36
B9: Opearating Profit | C9: =Model!C29 -> 872.2 | D9: =Model!D29 -> 1367.4 | E9: =Model!E29 -> 1829.7 | F9: =Model!F29 -> 2511.2822 | G9: =Model!G29 -> 3467.3023 | H9: =Model!H29 -> 4397.6426 | I9: =Model!I29 -> 5356.9434
B10: Opearting Margin | C10: =C9/C6 -> 0.12708358 | D10: =D9/D6 -> 0.17067326 | E10: =E9/E6 -> 0.17885805 | F10: =F9/F6 -> 0.18457484 | G10: =G9/G6 -> 0.19755088 | H10: =H9/H6 -> 0.2053749 | I10: =I9/I6 -> 0.21382507
B11: Net Income | C11: =Model!C38 -> 460.2 | D11: =Model!D38 -> 495.8 | E11: =Model!E38 -> 1332.8 | F11: =Model!F38 -> 1805.625 | G11: =Model!G38 -> 2537.812 | H11: =Model!H38 -> 3250.3541 | I11: =Model!I38 -> 3985.0509
B12: Net Margin | C12: =C11/C6 -> 0.06705327 | D12: =D11/D6 -> 0.061883722 | E12: =E11/E6 -> 0.13028475 | F12: =F11/F6 -> 0.13271027 | G12: =G11/G6 -> 0.14459282 | H12: =H11/H6 -> 0.15179522 | I12: =I11/I6 -> 0.1590653
B13: Operating Cash flow | C13: =Model!C112 -> 900.5 | D13: =Model!D112 -> 1319.3 | E13: =Model!E112 -> 2113.8 | F13: =Model!F112 -> 2592.601 | G13: =Model!G112 -> 2505.3321 | H13: =Model!H112 -> 3209.2658 | I13: =Model!I112 -> 4089.9432
B14: Capital Expenditures | C14: =Model!C115 -> -127.9 | D14: =Model!D115 -> -167 | E14: =Model!E115 -> -220 | F14: =Model!F115 -> -476.20185 | G14: =Model!G115 -> -526.54318 | H14: =Model!H115 -> -535.3189 | I14: =Model!I115 -> -501.05849
B15: Free Cash Flow (OCF + CAPEX) | C15: =SUM(C13:C14) -> 772.6 | D15: =SUM(D13:D14) -> 1152.3 | E15: =SUM(E13:E14) -> 1893.8 | F15: =SUM(F13:F14) -> 2116.3992 | G15: =SUM(G13:G14) -> 1978.789 | H15: =SUM(H13:H14) -> 2673.9469 | I15: =SUM(I13:I14) -> 3588.8847
B16: Cash and Cash Equivalents (B/s) | C16: =Model!C46 -> 780.4 | D16: =Model!D46 -> 1227.6 | E16: =Model!E46 -> 1728.4 | F16: =Model!F46 -> 3426.7179 | G16: =Model!G46 -> 5257.7163 | H16: =Model!H46 -> 7748.2455 | I16: =Model!I46 -> 11116.978
B17: Total Debt | C17: =Model!C70+Model!C78 -> 2940.9 | D17: =Model!D70+Model!D78 -> 2928.2 | E17: =Model!E70+Model!E78 -> 2913 | F17: =Model!F70+Model!F78 -> 2892.1 | G17: =Model!G70+Model!G78 -> 2871.2 | H17: =Model!H70+Model!H78 -> 2850.3 | I17: =Model!I70+Model!I78 -> 2829.4
B18: Net Cash / (Net Debt) | C18: =Model!C46+Model!C47-Model!C70-Model!C78 -> -2160.5 | D18: =Model!D46+Model!D47-Model!D70-Model!D78 -> -1700.6 | E18: =Model!E46+Model!E47-Model!E70-Model!E78 -> -1085.1 | F18: =Model!F46+Model!F47-Model!F70-Model!F78 -> 634.11792 | G18: =Model!G46+Model!G47-Model!G70-Model!G78 -> 2486.0163 | H18: =Model!H46+Model!H47-Model!H70-Model!H78 -> 4997.4455 | I18: =Model!I46+Model!I47-Model!I70-Model!I78 -> 8387.0776

Sheet Model
B2: VERTIV HOLDINGS (VRT)
B3: 3 Statement Projection Model
B5: Key
B6: Blue Text | C6: Historical data/Input/Assumption
B7: Black Text | C7: Formulas/Calculation
B9: INCOME STATEMENT
B10: $ in millions, fiscal years ending Dec 31
C12: 2023A | D12: 2024A | E12: 2025A | F12: 2026E | G12: 2027E | H12: 2028E | I12: 2029E
B13: Net sales
B14: Net sales - Products | C14: 5406.1 | D14: 6393.5 | E14: 8390.6
B15: Net sales - Services | C15: 1457.1 | D15: 1618.3 | E15: 1839.3
B16: Total Net sales | C16: =SUM(C14:C15) -> 6863.2 | D16: =SUM(D14:D15) -> 8011.8 | E16: =SUM(E14:E15) -> 10229.9 | F16: =E16*(1+F196) -> 13605.767 | G16: =F16*(1+G196) -> 17551.439 | H16: =G16*(1+H196) -> 21412.756 | I16: =H16*(1+I196) -> 25052.925
B18: Cost of Sales
B19: COS - Products | C19: 3575.7 | D19: 4099.4 | E19: 5447.2
B20: COS - Services | C20: 887 | D20: 978.2 | E20: 1067.5
B21: Total Cost of Sales | C21: =SUM(C19:C20) -> 4462.7 | D21: =SUM(D19:D20) -> 5077.6 | E21: =SUM(E19:E20) -> 6514.7 | F21: =F16-F22 -> 8707.6909 | G21: =G16-G22 -> 11232.921 | H21: =H16-H22 -> 13704.164 | I21: =I16-I22 -> 16033.872
B22: Gross Profit | C22: =C16-C21 -> 2400.5 | D22: =D16-D21 -> 2934.2 | E22: =E16-E21 -> 3715.2 | F22: =F16*F199 -> 4898.0761 | G22: =G16*G199 -> 6318.5182 | H22: =H16*H199 -> 7708.5922 | I22: =I16*I199 -> 9019.0529
B24: Operating Costs
B25: SGA | C25: 1312.3 | D25: 1374 | E25: 1617.8 | F25: =F16*F202 -> 2040.865 | G25: =G16*G202 -> 2544.9587 | H25: =H16*H202 -> 2997.7859 | I25: =I16*I202 -> 3382.1448
B26: Amortization of intangibles | C26: 181.3 | D26: 184.2 | E26: 200.4 | F26: 277.9 | G26: 218.5 | H26: 206.1 | I26: 154.7
B27: Other Operating expenses | C27: 34.7 | D27: 8.6 | E27: 67.3 | F27: =F16*F207 -> 68.028835 | G27: =G16*G207 -> 87.757197 | H27: =H16*H207 -> 107.06378 | I27: =I16*I207 -> 125.26462
B28: Total Operating Costs | C28: =SUM(C25:C27) -> 1528.3 | D28: =SUM(D25:D27) -> 1566.8 | E28: =SUM(E25:E27) -> 1885.5 | F28: =SUM(F25:F27) -> 2386.7939 | G28: =SUM(G25:G27) -> 2851.2159 | H28: =SUM(H25:H27) -> 3310.9496 | I28: =SUM(I25:I27) -> 3662.1094
B29: Operating Profit | C29: =C22-C28 -> 872.2 | D29: =D22-D28 -> 1367.4 | E29: =E22-E28 -> 1829.7 | F29: =F22-F28 -> 2511.2822 | G29: =G22-G28 -> 3467.3023 | H29: =H22-H28 -> 4397.6426 | I29: =I22-I28 -> 5356.9434
B31: Non Operating Expenses
B32: Interest expense, net | C32: 180.1 | D32: 150.4 | E32: 86.1 | F32: =F246 -> 150.98811 | G32: =G246 -> 149.90091 | H32: =H246 -> 148.81371 | I32: =I246 -> 147.72651
B33: Loss on extinguishment of debt | C33: 0.5 | D33: 2.4 | E33: 1.7 | F33: 0 | G33: 0 | H33: 0 | I33: 0
B34: Change in fair value of warrant liabilities | C34: 157.9 | D34: 449.2 | E34: 0 | F34: 0 | G34: 0 | H34: 0 | I34: 0
B35: Total non operating expenses | C35: =SUM(C32:C34) -> 338.5 | D35: =SUM(D32:D34) -> 602 | E35: =SUM(E32:E34) -> 87.8 | F35: =SUM(F32:F34) -> 150.98811 | G35: =SUM(G32:G34) -> 149.90091 | H35: =SUM(H32:H34) -> 148.81371 | I35: =SUM(I32:I34) -> 147.72651
B36: Earnings Before Tax | C36: =C29-C35 -> 533.7 | D36: =D29-D35 -> 765.4 | E36: =E29-E35 -> 1741.9 | F36: =F29-F35 -> 2360.2941 | G36: =G29-G35 -> 3317.4014 | H36: =H29-H35 -> 4248.8289 | I36: =I29-I35 -> 5209.2169
B37: Income tax expense | C37: 73.5 | D37: 269.6 | E37: 409.1 | F37: =F36*F213 -> 554.66912 | G37: =G36*G213 -> 779.58932 | H37: =H36*H213 -> 998.47478 | I37: =I36*I213 -> 1224.166
B38: Net Income/(Loss) | C38: =C36-C37 -> 460.2 | D38: =D36-D37 -> 495.8 | E38: =E36-E37 -> 1332.8 | F38: =F36-F37 -> 1805.625 | G38: =G36-G37 -> 2537.812 | H38: =H36-H37 -> 3250.3541 | I38: =I36-I37 -> 3985.0509
B41: BALANCE SHEET
B43: ASSETS:
B45: Current Assets
B46: Cash and cash equivalents | C46: 780.4 | D46: 1227.6 | E46: 1728.4 | F46: =F151-$E$152 -> 3426.7179 | G46: =G151-$E$152 -> 5257.7163 | H46: =H151-$E$152 -> 7748.2455 | I46: =I151-$E$152 -> 11116.978
B47: Short-term investments | D47: 0 | E47: 99.5 | F47: =E47 -> 99.5 | G47: =F47 -> 99.5 | H47: =G47 -> 99.5 | I47: =H47 -> 99.5
B48: Accounts receivable | C48: 2118.1 | D48: 2362.7 | E48: 3109 | F48: =F256 -> 4100.3681 | G48: =G256 -> 5289.4749 | H48: =H256 -> 6453.1594 | I48: =I256 -> 7550.1965
B49: Inventories | C49: 884.3 | D49: 1244.4 | E49: 1456.5 | F49: =F257 -> 2385.6687 | G49: =G257 -> 2769.7614 | H49: =H257 -> 3191.3806 | I49: =I257 -> 3514.2733
B50: Other current assets | C50: 218.7 | D50: 267.1 | E50: 426.1 | F50: =F258 -> 530.62491 | G50: =G258 -> 684.50614 | H50: =H258 -> 835.09749 | I50: =I258 -> 977.06406
B51: Total Current Assets | C51: =SUM(C46:C50) -> 4001.5 | D51: =SUM(D46:D50) -> 5101.8 | E51: =SUM(E46:E50) -> 6819.5 | F51: =SUM(F46:F50) -> 10542.88 | G51: =SUM(G46:G50) -> 14100.959 | H51: =SUM(H46:H50) -> 18327.383 | I51: =SUM(I46:I50) -> 23258.011
...

Sheet Assumptions - Detailed
A2: Revenue Growth
A4: 2026 total sales growth: 33% (~$13.6B)
A6: Guidance: In its Q2 2026 release, Vertiv guided full-year net sales of $13.8B to $14.2B (midpoint $14B), which is about 37% total growth over 2025's $10.23B. Organic growth guidance is 30 to 32%; the gap is acquisitions and currency.
A7: Track record: Vertiv has beaten its sales guidance in each of the last two years. For 2025, it guided around $9B at the end of 2024 and delivered $10.23B. This suggests management guides conservatively, which argues for staying close to guidance.
A8: Year to date: H1 2026 sales were $5.92B (Q1 $2.65B, Q2 $3.27B), about 42% of the $14B guidance. In 2025, H1 was about 46% of the full year. If 2026 followed the same seasonal pattern, full-year sales would be around $13B, below guidance. Hitting $14B requires H2 to accelerate meaningfully, with Q4 around $4.3B versus $2.88B in Q4 2025 (roughly 50% growth).
A9: Support for H2 acceleration: Q3 guidance calls for 34 to 36% organic growth, faster than H1. Deferred revenue rose from 9.3% to 17.7% of sales between 2023 and 2025, showing customers are prepaying for future deliveries. Both point to a strong second half.
A10: Historical anchor: 2023–25 sales CAGR was 22%. This reflects the period before the AI buildout was fully underway, so it's used as the long-run level growth fades toward by 2029, not as a check on 2026.
A11: Conclusion: 33% sits between the seasonal estimate (~$13B) and guidance ($14B). It gives credit to Vertiv's track record and H2 visibility, while allowing for the risk that H2 doesn't fully deliver.
A12: Risks: Upside if Vertiv beats guidance again (35 to 38%). Downside if data center capex slows or deliveries slip into 2027 (28 to 30%).
A14: H1 - Gross Profit Margin
B15: 2026 | C15: 2025 | D15: 2024
A16: Net sales | B16: 5923.8 | C16: 4674.1 | D16: 3591.9 | E16: =((B16/D16)^(1/2))-1 -> 0.284216
A17: COGS | B17: 3689.2 | C17: 3091 | D17: 2284.3 | E17: =((B17/D17)^(1/2))-1 -> 0.27083606
A18: GPM | B18: =(B16-B17)/B16 -> 0.37722408 | C18: =(C16-C17)/C16 -> 0.33869622 | D18: =(D16-D17)/D16 -> 0.36404132
A20: PPE SCHEDULE
A21: CAPEX Assumption
A22: Capex H1 2025 | C22: =81.5 -> 81.5
A23: Sales H1 2025 | C23: 4674.1
A24: Capex as % of sales - H1 2025 | C24: =C22/C23 -> 0.017436512
A25: Avg CAPEX (2023-2025) | C25: 0.0203
A26: Pedicted CAPEX in Q2 2026 | C26: 0.04
A28: Depreciation]
A29: H1 2026 DEP | C29: =66.92*2 -> 133.84
A30: H1 2026 PPE | C30: =Model!F219 -> 921.8
A31: H1 dep as % to Opening PPE | C31: =C29/C30 -> 0.14519419
A32: AVG (2023 - 2025) | C32: 0.1505
A34: Goodwill | D34: Additions from acquisitions (Q2 2026)
A35: Goodwill 2025 | B35: 2033.7 | D35: Intangibles 2025 year end | G35: 1894.8
A36: Goodwill 2026 - Q2 | B36: 2283.3 | D36: Intangibles 2026 Q2 | G36: 1800.8
A37: Goodwill acquired | B37: =B36-B35 -> 249.6 | D37: H1 amortization | G37: 151.3
G38: =G36-G35+G37 -> 57.3
A39: Repayments | B39: 20.9
A46: Mandatory repayments of $20.9M a year per the 10-K maturity table; the ~$850M 2028 maturity is assumed to be refinanced
A48: Interest Expense
A57: Total Debt 2025 | B57: 2913 | E57: Debt | F57: Interest (P.a) | G57: Weights
B58: =B57+13.1 -> 2926.1 | D58: Term loan - Floating | E58: 2076.1 | F58: =E58*5.61% -> 116.46921 | G58: =E58/B58 -> 0.70951095 | H58: 0.0561 | I58: =H58*G58 -> 0.039803564
D59: Senior secured noted - Refinanced | E59: 850 | F59: =E59*4.125% -> 35.0625 | G59: =E59/B58 -> 0.29048905 | H59: 0.04125 | I59: =H59*G59 -> 0.011982673
E60: =SUM(E58:E59) -> 2926.1 | F60: =SUM(F58:F59) -> 151.53171 | I60: =SUM(I58:I59) -> 0.051786238
D62: Int Rate | F62: =F60/B57 -> 0.052019125
A63: 2 methods used to verify - Weighted avg and second is int rate calc
...

Sheet Methodology - Each Step
A1: STEP 3: Assumptions
A3: Revenue growth 2026 (33%) – Q2 2026 earnings release – guidance $14B vs H1 seasonality (~$13B), picked in between
A4: Revenue growth 2027 (29%) – Yahoo Finance consensus – used analysts' growth rate, not their dollar figure
A5: Revenue growth 2028 (22%) – Simply Wall St consensus (~21%) – rounded to historical CAGR
A6: Revenue growth 2029 (17%) – own judgment – fade as AI cycle matures
A7: Gross margin (36%) – 10-K + Q2 10-Qs – average of FY 2023–25 and H1 2024–26
A8: SG&A (15% → 13.5%) – own ratios + Morningstar – slower decline than historical trend
A9: Amortization – 10-K intangibles note – copied the estimated future amortization table
A10: Other opex (0.5%) – own ratios – historical average % of sales
A11: Interest – 10-K – held at 2025 level, placeholder until debt schedule
A12: Warrants, debt extinguishment – set to zero – one-offs
A13: Tax rate (23.5%) – own ratios – 2025 rate, only clean year
